Workbook

Sheet Cover
B2: Asset Based Lending Credit Analysis
B3: Borrowing Base and Cash Flow Stress Test | Genuine Parts Company (GPC)
B5: Project Use
B6: Purpose | C6: Estimate ABL borrowing capacity from SEC financials. Stress AR, inventory, reserves, liquidity, and cash-flow support.
B8: Workbook map
B10: Sources | C10: SEC filings, XBRL tags, and assumption notes.
B11: Historical Financials | C11: Reported history and lender-style liquidity ratios.
B12: ABL Assumptions | C12: Editable scenario drivers; blue font marks inputs.
B13: AR Aging / Inventory / Customer Concentration | C13: Collateral eligibility schedules for ABL controls.
B14: Borrowing Base | C14: Eligible collateral x advance rates, less reserves, vs. loan balance.
B15: Cash Flow Stress | C15: Base/downside/stress repayment capacity and liquidity outputs.
B16: Dashboard | C16: Credit committee style summary view.
B17: Checks | C17: Tie-outs and model-status tests.
B20: Key modeling caveat | C20: ABL detail schedules are illustrative. Scaled to FY2025 reported AR and inventory.
B24: Latest annual filing | C24: 10-K filed 2026-02-20
B25: Latest quarterly filing context | C25: 10-Q filed 2026-04-21

Sheet Sources
A1: Sources and Audit Trail
A3: Company | B3: GENUINE PARTS CO
A4: CIK | B4: 0000040987
A5: SIC | B5: 5013 - Wholesale-Motor Vehicle Supplies & New Parts
A7: SEC companyfacts API
A8: SEC submissions API
A10: Metric | B10: Year | C10: Value ($mm) | D10: SEC Tag | E10: Form | F10: Filed | G10: Accession | H10: URL / Notes
A11: Revenue | B11: 2021 | C11: 18870.51 | D11: RevenueFromContractWithCustomerExcludingAssessedTax | E11: 10-K | F11: 2024-02-22 | G11: 0000040987-24-000024 | H11: SEC filing
A12: Revenue | B12: 2022 | C12: 22095.973 | D12: RevenueFromContractWithCustomerExcludingAssessedTax | E12: 10-K | F12: 2025-02-21 | G12: 0000040987-25-000026 | H12: SEC filing
A13: Revenue | B13: 2023 | C13: 23090.61 | D13: RevenueFromContractWithCustomerExcludingAssessedTax | E13: 10-K | F13: 2026-02-20 | G13: 0000040987-26-000003 | H13: SEC filing
A14: Revenue | B14: 2024 | C14: 23486.569 | D14: RevenueFromContractWithCustomerExcludingAssessedTax | E14: 10-K | F14: 2026-02-20 | G14: 0000040987-26-000003 | H14: SEC filing
A15: Revenue | B15: 2025 | C15: 24300.141 | D15: RevenueFromContractWithCustomerExcludingAssessedTax | E15: 10-K | F15: 2026-02-20 | G15: 0000040987-26-000003 | H15: SEC filing
A16: Pretax income | B16: 2021 | C16: 1200.346 | D16: IncomeLossFromContinuingOperationsBeforeIncomeTaxesExtraordinaryItemsNoncontrollingInterest | E16: 10-K | F16: 2024-02-22 | G16: 0000040987-24-000024 | H16: SEC filing
A17: Pretax income | B17: 2022 | C17: 1572.602 | D17: IncomeLossFromContinuingOperationsBeforeIncomeTaxesExtraordinaryItemsNoncontrollingInterest | E17: 10-K | F17: 2025-02-21 | G17: 0000040987-25-000026 | H17: SEC filing
A18: Pretax income | B18: 2023 | C18: 1742.348 | D18: IncomeLossFromContinuingOperationsBeforeIncomeTaxesExtraordinaryItemsNoncontrollingInterest | E18: 10-K | F18: 2026-02-20 | G18: 0000040987-26-000003 | H18: SEC filing
A19: Pretax income | B19: 2024 | C19: 1175.968 | D19: IncomeLossFromContinuingOperationsBeforeIncomeTaxesExtraordinaryItemsNoncontrollingInterest | E19: 10-K | F19: 2026-02-20 | G19: 0000040987-26-000003 | H19: SEC filing
A20: Pretax income | B20: 2025 | C20: 52.168 | D20: IncomeLossFromContinuingOperationsBeforeIncomeTaxesExtraordinaryItemsNoncontrollingInterest | E20: 10-K | F20: 2026-02-20 | G20: 0000040987-26-000003 | H20: SEC filing
A21: Income tax expense | B21: 2021 | C21: 301.556 | D21: IncomeTaxExpenseBenefit | E21: 10-K | F21: 2024-02-22 | G21: 0000040987-24-000024 | H21: SEC filing
A22: Income tax expense | B22: 2022 | C22: 389.901 | D22: IncomeTaxExpenseBenefit | E22: 10-K | F22: 2025-02-21 | G22: 0000040987-25-000026 | H22: SEC filing
... A43: Interest expense | B43: 2023 | C43: 64.469 | D43: InterestExpense | E43: 10-K | F43: 2024-02-22 | G43: 0000040987-24-000024 | H43: SEC filing
A44: Interest expense | B44: 2024 | D44: InterestExpense | H44: No source fact extracted.
A45: Interest expense | B45: 2025 | D45: InterestExpense | H45: No source fact extracted.
A46: Interest paid | B46: 2021 | C46: 65.732 | D46: InterestPaidNet | E46: 10-K | F46: 2024-02-22 | G46: 0000040987-24-000024 | H46: SEC filing
A47: Interest paid | B47: 2022 | C47: 73.368 | D47: InterestPaidNet | E47: 10-K | F47: 2025-02-21 | G47: 0000040987-25-000026 | H47: SEC filing
A48: Interest paid | B48: 2023 | C48: 90.405 | D48: InterestPaidNet | E48: 10-K | F48: 2026-02-20 | G48: 0000040987-26-000003 | H48: SEC filing
A49: Interest paid | B49: 2024 | C49: 124.977 | D49: InterestPaidNet | E49: 10-K | F49: 2026-02-20 | G49: 0000040987-26-000003 | H49: SEC filing
A50: Interest paid | B50: 2025 | C50: 191.334 | D50: InterestPaidNet | E50: 10-K | F50: 2026-02-20 | G50: 0000040987-26-000003 | H50: SEC filing
A51: Depreciation and amortization | B51: 2021 | C51: 290.971 | D51: DepreciationAndAmortization | E51: 10-K | F51: 2024-02-22 | G51: 0000040987-24-000024 | H51: SEC filing
A52: Depreciation and amortization | B52: 2022 | C52: 347.819 | D52: DepreciationAndAmortization | E52: 10-K | F52: 2025-02-21 | G52: 0000040987-25-000026 | H52: SEC filing
A53: Depreciation and amortization | B53: 2023 | C53: 350.529 | D53: DepreciationAndAmortization | E53: 10-K | F53: 2026-02-20 | G53: 0000040987-26-000003 | H53: SEC filing
A54: Depreciation and amortization | B54: 2024 | C54: 407.978 | D54: DepreciationAndAmortization | E54: 10-K | F54: 2026-02-20 | G54: 0000040987-26-000003 | H54: SEC filing
A55: Depreciation and amortization | B55: 2025 | C55: 538.023 | D55: DepreciationAndAmortization | E55: 10-K | F55: 2026-02-20 | G55: 0000040987-26-000003 | H55: SEC filing
A56: Cash, cash equivalents and restricted cash | B56: 2021 | C56: 714.701 | D56: CashCashEquivalentsRestrictedCashAndRestrictedCashEquivalents | E56: 10-K | F56: 2025-02-21 | G56: 0000040987-25-000026 | H56: SEC filing
A57: Cash, cash equivalents and restricted cash | B57: 2022 | C57: 653.463 | D57: CashCashEquivalentsRestrictedCashAndRestrictedCashEquivalents | E57: 10-K | F57: 2026-02-20 | G57: 0000040987-26-000003 | H57: SEC filing
... A80: Current liabilities | B80: 2025 | C80: 9787.705 | D80: LiabilitiesCurrent | E80: 10-K | F80: 2026-02-20 | G80: 0000040987-26-000003 | H80: SEC filing
A81: Short-term borrowings | B81: 2021 | C81: 0 | D81: ShortTermBorrowings | H81: Modeled as zero because the SEC tag was not reported.
A82: Short-term borrowings | B82: 2022 | C82: 0 | D82: ShortTermBorrowings | H82: Modeled as zero because the SEC tag was not reported.
A83: Short-term borrowings | B83: 2023 | C83: 0 | D83: ShortTermBorrowings | H83: Modeled as zero because the SEC tag was not reported.
A84: Short-term borrowings | B84: 2024 | C84: 41.705 | D84: ShortTermBorrowings | E84: 10-K | F84: 2026-02-20 | G84: 0000040987-26-000003 | H84: SEC filing
A85: Short-term borrowings | B85: 2025 | C85: 943.54 | D85: ShortTermBorrowings | E85: 10-K | F85: 2026-02-20 | G85: 0000040987-26-000003 | H85: SEC filing
...

Sheet Historical Financials
A1: Historical Financials
A2: USD in millions except ratios. SEC-sourced inputs include cell comments with tag and filing references.
A4: Fiscal year | B4: 2021 | C4: 2022 | D4: 2023 | E4: 2024 | F4: 2025 | G4: Notes
A5: Revenue | B5: 18870.51 | C5: 22095.973 | D5: 23090.61 | E5: 23486.569 | F5: 24300.141
A6: Revenue growth | C6: =C5/B5-1 -> 0.17092612 | D6: =D5/C5-1 -> 0.045014401 | E6: =E5/D5-1 -> 0.017148053 | F6: =F5/E5-1 -> 0.034639883
A7: Pretax income | B7: 1200.346 | C7: 1572.602 | D7: 1742.348 | E7: 1175.968 | F7: 52.168
A8: Interest expense / paid fallback | B8: 62.15 | C8: 73.887 | D8: 64.469 | E8: 124.977 | F8: 191.334 | G8: Uses InterestExpense where reported; InterestPaidNet fallback for 2024-2025.
A9: Depreciation & amortization | B9: 290.971 | C9: 347.819 | D9: 350.529 | E9: 407.978 | F9: 538.023
A10: EBITDA proxy | B10: =B7+B8+B9 -> 1553.467 | C10: =C7+C8+C9 -> 1994.308 | D10: =D7+D8+D9 -> 2157.346 | E10: =E7+E8+E9 -> 1708.923 | F10: =F7+F8+F9 -> 781.525 | G10: Analyst proxy for lending review; not company-reported adjusted EBITDA or a formal operating CCC metric.
A11: EBITDA margin | B11: =B10/B5 -> 0.08232247 | C11: =C10/C5 -> 0.090256627 | D11: =D10/D5 -> 0.09342958 | E11: =E10/E5 -> 0.072761713 | F11: =F10/F5 -> 0.032161336
A12: Net income | B12: 898.79 | C12: 1182.701 | D12: 1316.524 | E12: 904.076 | F12: 65.945
A13: Operating cash flow | B13: 1258.285 | C13: 1466.971 | D13: 1435.61 | E13: 1251.251 | F13: 890.762
A14: Capital expenditures | B14: 266.136 | C14: 339.632 | D14: 512.675 | E14: 567.339 | F14: 469.838
A15: Free cash flow | B15: =B13-B14 -> 992.149 | C15: =C13-C14 -> 1127.339 | D15: =D13-D14 -> 922.935 | E15: =E13-E14 -> 683.912 | F15: =F13-F14 -> 420.924
A16: Accounts receivable | B16: 1797.955 | C16: 2188.868 | D16: 2223.431 | E16: 2182.856 | F16: 2370.939
A17: Inventory | B17: 3889.919 | C17: 4441.649 | D17: 4676.686 | E17: 5514.427 | F17: 6071.996
A18: Cash and restricted cash | B18: 714.701 | C18: 653.463 | D18: 1102.007 | E18: 479.991 | F18: 477.179
A19: Current assets | B19: 7756.422 | C19: 8816.739 | D19: 9605.852 | E19: 9852.584 | F19: 10564.734
A20: Current liabilities | B20: 6581.583 | C20: 7686.11 | D20: 7827.109 | E20: 8525.38 | F20: 9787.705
A21: Short-term borrowings | B21: 0 | C21: 0 | D21: 0 | E21: 41.705 | F21: 943.54
A22: Commercial paper | B22: 0 | C22: 0 | D22: 0 | E22: 0 | F22: 343
A23: Current maturities of long-term debt | B23: 0 | C23: 252.029 | D23: 355.298 | E23: 500 | F23: 353.788
A24: Long-term debt, noncurrent | B24: 2409.363 | C24: 3076.794 | D24: 3550.93 | E24: 3742.64 | F24: 3498.423
A25: Total debt | B25: =SUM(B21:B24) -> 2409.363 | C25: =SUM(C21:C24) -> 3328.823 | D25: =SUM(D21:D24) -> 3906.228 | E25: =SUM(E21:E24) -> 4284.345 | F25: =SUM(F21:F24) -> 5138.751
A26: Net debt | B26: =B25-B18 -> 1694.662 | C26: =C25-C18 -> 2675.36 | D26: =D25-D18 -> 2804.221 | E26: =E25-E18 -> 3804.354 | F26: =F25-F18 -> 4661.572
A27: Current ratio | B27: =B19/B20 -> 1.178504 | C27: =C19/C20 -> 1.1471003 | D27: =D19/D20 -> 1.2272541 | E27: =E19/E20 -> 1.1556768 | F27: =F19/F20 -> 1.0793883
A28: Quick ratio | B28: =(B18+B16)/B20 -> 0.38177077 | C28: =(C18+C16)/C20 -> 0.36980098 | D28: =(D18+D16)/D20 -> 0.42486159 | E28: =(E18+E16)/E20 -> 0.3123435 | F28: =(F18+F16)/F20 -> 0.29098936
A29: DSO | B29: =B16/B5*365 -> 34.776674 | C29: =C16/C5*365 -> 36.157576 | D29: =D16/D5*365 -> 35.146422 | E29: =E16/E5*365 -> 33.923322 | F29: =F16/F5*365 -> 35.612663
A30: Inventory days (sales-based) | B30: =B17/B5*365 -> 75.240173 | C30: =C17/C5*365 -> 73.370921 | D30: =D17/D5*365 -> 73.925738 | E30: =E17/E5*365 -> 85.69859 | F30: =F17/F5*365 -> 91.204349
A31: Current liability days (sales-based) | B31: =B20/B5*365 -> 127.30328 | C31: =C20/C5*365 -> 126.96568 | D31: =D20/D5*365 -> 123.72539 | E31: =E20/E5*365 -> 132.4912 | F31: =F20/F5*365 -> 147.01612
A32: Cash conversion cycle proxy | B32: =B29+B30-B31 -> -17.286432 | C32: =C29+C30-C31 -> -17.437179 | D32: =D29+D30-D31 -> -14.653233 | E32: =E29+E30-E31 -> -12.869287 | F32: =F29+F30-F31 -> -20.199103 | G32: Analyst proxy for lending review; not company-reported adjusted EBITDA or a formal operating CCC metric.
A33: Debt / EBITDA | B33: =B25/B10 -> 1.5509586 | C33: =C25/C10 -> 1.6691619 | D33: =D25/D10 -> 1.8106637 | E33: =E25/E10 -> 2.5070439 | F33: =F25/F10 -> 6.5752868
A34: EBITDA / interest | B34: =B10/B8 -> 24.995447 | C34: =C10/C8 -> 26.991325 | D34: =D10/D8 -> 33.463308 | E34: =E10/E8 -> 13.6739 | F34: =F10/F8 -> 4.0846112

Sheet ABL Assumptions
A1: ABL Assumptions
A2: Blue-font cells are editable scenario assumptions. Values shown are illustrative lender assumptions.
A4: Driver | B4: Base | C4: Downside | D4: Stress | E4: Rationale
A5: Revenue growth / shock | B5: 0.02 | C5: -0.08 | D5: -0.18 | E5: Revenue stress drives AR balance and borrower cash flow.
A6: EBITDA margin change | B6: 0 | C6: -0.015 | D6: -0.03 | E6: Downside cases compress cash-flow repayment capacity.
A7: AR eligible % | B7: 0.92 | C7: 0.87 | D7: 0.8 | E7: Excludes 90+ day, disputed, affiliate, unsupported foreign, and cross-aged receivables.
A8: AR advance rate | B8: 0.85 | C8: 0.825 | D8: 0.8 | E8: Typical ABL AR advance range for eligible receivables.
A9: Inventory balance change | B9: 0.02 | C9: 0.08 | D9: 0.12 | E9: Downside assumes inventory builds while eligibility and NOLV support deteriorate.
A10: Inventory eligible % | B10: 0.75 | C10: 0.65 | D10: 0.55 | E10: Excludes obsolete, consigned, slow-moving, and unsupported offsite inventory.
A11: Inventory advance rate | B11: 0.5 | C11: 0.45 | D11: 0.4 | E11: Applied against eligible inventory; conservative vs. AR advance.
A12: Dilution reserve % of gross AR | B12: 0.02 | C12: 0.035 | D12: 0.05 | E12: Proxy for credits, disputes, returns, and unapplied cash.
A13: Concentration reserve % of gross AR | B13: 0.015 | C13: 0.03 | D13: 0.05 | E13: Proxy for obligor concentration above borrowing-base limits.
A14: Other reserves ($mm) | B14: 150 | C14: 250 | D14: 350 | E14: Rent, freight, tax, and other collateral-control reserves.
A15: Availability block ($mm) | B15: 100 | C15: 150 | D15: 200 | E15: Minimum cushion retained by the lender.
A16: ABL loan balance change | B16: 0 | C16: 0.1 | D16: 0.2 | E16: Downside assumes higher revolver draw / working-capital funding need.
... A19: Capex % of revenue | B19: 0.02 | C19: 0.022 | D19: 0.025 | E19: Simplified maintenance and growth capex assumption.

Sheet AR Aging
A1: AR Aging and Eligibility
A2: Illustrative borrowing-base certificate schedule scaled to reported FY2025 accounts receivable.
A4: Reported 2025 AR | B4: ='Historical Financials'!F16 -> 2370.939
A6: Bucket / Exclusion | B6: % of AR | C6: Gross AR | D6: Ineligible % | E6: Eligible AR | F6: Advance Rate | G6: Advance Value | H6: ABL treatment
A7: Current | B7: 0.58 | C7: =$B$4*B7 -> 1375.1446 | D7: 0 | E7: =C7*(1-D7) -> 1375.1446 | F7: ='ABL Assumptions'!B7 -> 0.85 | G7: =E7*F7 -> 1168.8729 | H7: Eligible if billed, earned, and not contra/affiliate.
A8: 1-30 days past due | B8: 0.2 | C8: =$B$4*B8 -> 474.1878 | D8: 0 | E8: =C8*(1-D8) -> 474.1878 | F8: ='ABL Assumptions'!B7 -> 0.85 | G8: =E8*F8 -> 403.05963 | H8: Normally eligible subject to concentration and dilution controls.
A9: 31-60 days past due | B9: 0.1 | C9: =$B$4*B9 -> 237.0939 | D9: 0.1 | E9: =C9*(1-D9) -> 213.38451 | F9: ='ABL Assumptions'!B7 -> 0.85 | G9: =E9*F9 -> 181.37683 | H9: Partial haircut for aging deterioration.
A10: 61-90 days past due | B10: 0.05 | C10: =$B$4*B10 -> 118.54695 | D10: 0.25 | E10: =C10*(1-D10) -> 88.910213 | F10: ='ABL Assumptions'!B7 -> 0.85 | G10: =E10*F10 -> 75.573681 | H10: Higher ineligibility due to near-threshold aging.
A11: 90+ days past due | B11: 0.04 | C11: =$B$4*B11 -> 94.83756 | D11: 1 | E11: =C11*(1-D11) -> 0 | F11: ='ABL Assumptions'!B7 -> 0.85 | G11: =E11*F11 -> 0 | H11: Typically ineligible under ABL borrowing-base rules.
A12: Disputed / offset | B12: 0.02 | C12: =$B$4*B12 -> 47.41878 | D12: 1 | E12: =C12*(1-D12) -> 0 | F12: ='ABL Assumptions'!B7 -> 0.85 | G12: =E12*F12 -> 0 | H12: Excluded due to dispute, credit memo, or payable offset.
A13: Affiliate / unsupported foreign | B13: 0.01 | C13: =$B$4*B13 -> 23.70939 | D13: 1 | E13: =C13*(1-D13) -> 0 | F13: ='ABL Assumptions'!B7 -> 0.85 | G13: =E13*F13 -> 0 | H13: Excluded without acceptable credit support.
A14: Total | B14: =SUM(B7:B13) -> 1 | C14: =SUM(C7:C13) -> 2370.939 | E14: =SUM(E7:E13) -> 2175.3365 | G14: =SUM(G7:G13) -> 1849.0361

Sheet Inventory Eligibility
A1: Inventory Eligibility
A2: Illustrative eligibility schedule scaled to reported FY2025 inventory.
A4: Reported 2025 inventory | B4: ='Historical Financials'!F17 -> 6071.996
A6: Inventory segment | B6: % of inventory | C6: Gross inventory | D6: Eligible % | E6: Eligible inventory | F6: Advance Rate | G6: Advance Value | H6: ABL treatment
A7: Finished goods / parts | B7: 0.72 | C7: =$B$4*B7 -> 4371.8371 | D7: 1 | E7: =C7*D7 -> 4371.8371 | F7: ='ABL Assumptions'!B10 -> 0.5 | G7: =E7*F7 -> 2185.9186 | H7: Primary collateral pool for an auto-parts distributor.
A8: Slow-moving inventory | B8: 0.1 | C8: =$B$4*B8 -> 607.1996 | D8: 0.5 | E8: =C8*D8 -> 303.5998 | F8: ='ABL Assumptions'!B10 -> 0.5 | G8: =E8*F8 -> 151.7999 | H8: Partial eligibility haircut due to turnover risk.
A9: Raw materials | B9: 0 | C9: =$B$4*B9 -> 0 | D9: 0 | E9: =C9*D9 -> 0 | F9: ='ABL Assumptions'!B10 -> 0.5 | G9: =E9*F9 -> 0 | H9: Not material for distributor model.
A10: Work-in-process | B10: 0 | C10: =$B$4*B10 -> 0 | D10: 0 | E10: =C10*D10 -> 0 | F10: ='ABL Assumptions'!B10 -> 0.5 | G10: =E10*F10 -> 0 | H10: Not material for distributor model.
A11: Obsolete inventory | B11: 0.05 | C11: =$B$4*B11 -> 303.5998 | D11: 0 | E11: =C11*D11 -> 0 | F11: ='ABL Assumptions'!B10 -> 0.5 | G11: =E11*F11 -> 0 | H11: Excluded from eligible inventory.
A12: Consigned inventory | B12: 0.04 | C12: =$B$4*B12 -> 242.87984 | D12: 0 | E12: =C12*D12 -> 0 | F12: ='ABL Assumptions'!B10 -> 0.5 | G12: =E12*F12 -> 0 | H12: Excluded unless lender has acceptable control agreement.
A13: Unsupported offsite inventory | B13: 0.03 | C13: =$B$4*B13 -> 182.15988 | D13: 0 | E13: =C13*D13 -> 0 | F13: ='ABL Assumptions'!B10 -> 0.5 | G13: =E13*F13 -> 0 | H13: Excluded without field exam/control support.
A14: Other eligible inventory | B14: 0.06 | C14: =$B$4*B14 -> 364.31976 | D14: 1 | E14: =C14*D14 -> 364.31976 | F14: ='ABL Assumptions'!B10 -> 0.5 | G14: =E14*F14 -> 182.15988 | H14: Eligible after standard reserves and NOLV haircut.
A15: Total | B15: =SUM(B7:B14) -> 1 | C15: =SUM(C7:C14) -> 6071.996 | E15: =SUM(E7:E14) -> 5039.7567 | G15: =SUM(G7:G14) -> 2519.8783

Sheet Customer Concentration
A1: Customer Concentration Risk
A2: Illustrative obligor schedule. Public filings do not provide AR by customer.
A4: Reported 2025 AR | B4: ='Historical Financials'!F16 -> 2370.939
A6: Customer | B6: % of AR | C6: AR balance | D6: Limit | E6: Excess over limit | F6: Reserve @ AR advance | G6: Flag | H6: Notes
A7: Customer A | B7: 0.14 | C7: =$B$4*B7 -> 331.93146 | D7: 0.1 | E7: =MAX(0,C7-$B$4*D7) -> 94.83756 | F7: =E7*'ABL Assumptions'!B7 -> 80.611926 | G7: =IF(B7>D7,"Breach","OK") -> Breach | H7: Concentration limit set at 10% for demonstration.
A8: Customer B | B8: 0.11 | C8: =$B$4*B8 -> 260.80329 | D8: 0.1 | E8: =MAX(0,C8-$B$4*D8) -> 23.70939 | F8: =E8*'ABL Assumptions'!B7 -> 20.152982 | G8: =IF(B8>D8,"Breach","OK") -> Breach | H8: Concentration limit set at 10% for demonstration.
A9: Customer C | B9: 0.08 | C9: =$B$4*B9 -> 189.67512 | D9: 0.1 | E9: =MAX(0,C9-$B$4*D9) -> 0 | F9: =E9*'ABL Assumptions'!B7 -> 0 | G9: =IF(B9>D9,"Breach","OK") -> OK | H9: Concentration limit set at 10% for demonstration.
A10: Customer D | B10: 0.07 | C10: =$B$4*B10 -> 165.96573 | D10: 0.1 | E10: =MAX(0,C10-$B$4*D10) -> 0 | F10: =E10*'ABL Assumptions'!B7 -> 0 | G10: =IF(B10>D10,"Breach","OK") -> OK | H10: Concentration limit set at 10% for demonstration.
A11: Customer E | B11: 0.06 | C11: =$B$4*B11 -> 142.25634 | D11: 0.1 | E11: =MAX(0,C11-$B$4*D11) -> 0 | F11: =E11*'ABL Assumptions'!B7 -> 0 | G11: =IF(B11>D11,"Breach","OK") -> OK | H11: Concentration limit set at 10% for demonstration.
A12: Customer F | B12: 0.05 | C12: =$B$4*B12 -> 118.54695 | D12: 0.1 | E12: =MAX(0,C12-$B$4*D12) -> 0 | F12: =E12*'ABL Assumptions'!B7 -> 0 | G12: =IF(B12>D12,"Breach","OK") -> OK | H12: Concentration limit set at 10% for demonstration.
A13: Customer G | B13: 0.04 | C13: =$B$4*B13 -> 94.83756 | D13: 0.1 | E13: =MAX(0,C13-$B$4*D13) -> 0 | F13: =E13*'ABL Assumptions'!B7 -> 0 | G13: =IF(B13>D13,"Breach","OK") -> OK | H13: Concentration limit set at 10% for demonstration.
A14: Customer H | B14: 0.03 | C14: =$B$4*B14 -> 71.12817 | D14: 0.1 | E14: =MAX(0,C14-$B$4*D14) -> 0 | F14: =E14*'ABL Assumptions'!B7 -> 0 | G14: =IF(B14>D14,"Breach","OK") -> OK | H14: Concentration limit set at 10% for demonstration.
A15: Customer I | B15: 0.02 | C15: =$B$4*B15 -> 47.41878 | D15: 0.1 | E15: =MAX(0,C15-$B$4*D15) -> 0 | F15: =E15*'ABL Assumptions'!B7 -> 0 | G15: =IF(B15>D15,"Breach","OK") -> OK | H15: Concentration limit set at 10% for demonstration.
A16: Customer J | B16: 0.015 | C16: =$B$4*B16 -> 35.564085 | D16: 0.1 | E16: =MAX(0,C16-$B$4*D16) -> 0 | F16: =E16*'ABL Assumptions'!B7 -> 0 | G16: =IF(B16>D16,"Breach","OK") -> OK | H16: Concentration limit set at 10% for demonstration.
A17: All other customers | B17: 0.385 | C17: =$B$4*B17 -> 912.81151 | D17: 0.1 | E17: =MAX(0,C17-$B$4*D17) -> 675.71762 | F17: =E17*'ABL Assumptions'!B7 -> 574.35997 | G17: =IF(B17>D17,"Breach","OK") -> Breach | H17: Concentration limit set at 10% for demonstration.
A18: Total | B18: =SUM(B7:B17) -> 1 | C18: =SUM(C7:C17) -> 2370.939 | F18: =SUM(F7:F17) -> 36.275367

Sheet Borrowing Base
A1: Borrowing Base Calculation
A2: Eligible AR plus eligible inventory, less reserves, compared with estimated ABL loan balance.
A4: Borrowing-base component | B4: Base | C4: Downside | D4: Stress | E4: Formula / Control
A5: Gross AR | B5: ='Historical Financials'!F16*(1+'ABL Assumptions'!B5) -> 2418.3578 | C5: ='Historical Financials'!F16*(1+'ABL Assumptions'!C5) -> 2181.2639 | D5: ='Historical Financials'!F16*(1+'ABL Assumptions'!D5) -> 1944.17 | E5: Reported AR scaled by revenue stress.
A6: AR eligible % | B6: ='ABL Assumptions'!B7 -> 0.92 | C6: ='ABL Assumptions'!C7 -> 0.87 | D6: ='ABL Assumptions'!D7 -> 0.8 | E6: Scenario assumption.
A7: Eligible AR | B7: =B5*B6 -> 2224.8892 | C7: =C5*C6 -> 1897.6996 | D7: =D5*D6 -> 1555.336 | E7: Gross AR x AR eligible %.
A8: AR advance rate | B8: ='ABL Assumptions'!B8 -> 0.85 | C8: ='ABL Assumptions'!C8 -> 0.825 | D8: ='ABL Assumptions'!D8 -> 0.8 | E8: Scenario assumption.
A9: AR availability | B9: =B7*B8 -> 1891.1558 | C9: =C7*C8 -> 1565.6021 | D9: =D7*D8 -> 1244.2688 | E9: Eligible AR x AR advance rate.
A10: Gross inventory | B10: ='Historical Financials'!F17*(1+'ABL Assumptions'!B9) -> 6193.4359 | C10: ='Historical Financials'!F17*(1+'ABL Assumptions'!C9) -> 6557.7557 | D10: ='Historical Financials'!F17*(1+'ABL Assumptions'!D9) -> 6800.6355 | E10: Reported inventory scaled by inventory build assumption.
A11: Inventory eligible % | B11: ='ABL Assumptions'!B10 -> 0.75 | C11: ='ABL Assumptions'!C10 -> 0.65 | D11: ='ABL Assumptions'!D10 -> 0.55 | E11: Scenario assumption.
A12: Eligible inventory | B12: =B10*B11 -> 4645.0769 | C12: =C10*C11 -> 4262.5412 | D12: =D10*D11 -> 3740.3495 | E12: Gross inventory x inventory eligible %.
A13: Inventory advance rate | B13: ='ABL Assumptions'!B11 -> 0.5 | C13: ='ABL Assumptions'!C11 -> 0.45 | D13: ='ABL Assumptions'!D11 -> 0.4 | E13: Scenario assumption.
A14: Inventory availability | B14: =B12*B13 -> 2322.5385 | C14: =C12*C13 -> 1918.1435 | D14: =D12*D13 -> 1496.1398 | E14: Eligible inventory x inventory advance rate.
A15: Total collateral availability | B15: =B9+B14 -> 4213.6943 | C15: =C9+C14 -> 3483.7457 | D15: =D9+D14 -> 2740.4086 | E15: AR availability + inventory availability.
A16: Dilution reserve | B16: =B5*'ABL Assumptions'!B12 -> 48.367156 | C16: =C5*'ABL Assumptions'!C12 -> 76.344236 | D16: =D5*'ABL Assumptions'!D12 -> 97.208499 | E16: Gross AR x dilution reserve %.
A17: Concentration reserve | B17: =MAX(B5*'ABL Assumptions'!B13,'Customer Concentration'!$F$18*B5/'Customer Concentration'!$C$18) -> 36.275367 | C17: =MAX(C5*'ABL Assumptions'!C13,'Customer Concentration'!$F$18*C5/'Customer Concentration'!$C$18) -> 65.437916 | D17: =MAX(D5*'ABL Assumptions'!D13,'Customer Concentration'!$F$18*D5/'Customer Concentration'!$C$18) -> 97.208499 | E17: Greater of scenario reserve and illustrative concentration schedule for Base.
A18: Other reserves | B18: ='ABL Assumptions'!B14 -> 150 | C18: ='ABL Assumptions'!C14 -> 250 | D18: ='ABL Assumptions'!D14 -> 350 | E18: Scenario assumption.
A19: Availability block | B19: ='ABL Assumptions'!B15 -> 100 | C19: ='ABL Assumptions'!C15 -> 150 | D19: ='ABL Assumptions'!D15 -> 200 | E19: Scenario assumption.
A20: Total reserves | B20: =SUM(B16:B19) -> 334.64252 | C20: =SUM(C16:C19) -> 541.78215 | D20: =SUM(D16:D19) -> 744.417 | E20: Sum of reserves.
A21: Borrowing base | B21: =B15-B20 -> 3879.0517 | C21: =C15-C20 -> 2941.9635 | D21: =D15-D20 -> 1995.9916 | E21: Total collateral availability less reserves.
A22: Estimated ABL loan balance | B22: =SUM('Historical Financials'!F21:F23)*(1+'ABL Assumptions'!B16) -> 1640.328 | C22: =SUM('Historical Financials'!F21:F23)*(1+'ABL Assumptions'!C16) -> 1804.3608 | D22: =SUM('Historical Financials'!F21:F23)*(1+'ABL Assumptions'!D16) -> 1968.3936 | E22: 2025 short-term borrowings + CP + current debt, adjusted by scenario.
A23: Excess availability | B23: =B21-B22 -> 2238.7237 | C23: =C21-C22 -> 1137.6027 | D23: =D21-D22 -> 27.598004 | E23: Borrowing base less loan balance.
A24: Utilization | B24: =B22/B21 -> 0.4228683 | C24: =C22/C21 -> 0.61331855 | D24: =D22/D21 -> 0.98617329 | E24: Loan balance / borrowing base.
A25: Minimum liquidity | B25: ='Historical Financials'!F18+B23 -> 2715.9027 | C25: ='Historical Financials'!F18+C23 -> 1614.7817 | D25: ='Historical Financials'!F18+D23 -> 504.777 | E25: Cash + excess availability.
A26: Availability alert | B26: =IF(B23<0,"Deficiency",IF(B23<500,"Low Availability","OK")) -> OK | C26: =IF(C23<0,"Deficiency",IF(C23<500,"Low Availability","OK")) -> OK | D26: =IF(D23<0,"Deficiency",IF(D23<500,"Low Availability","OK")) -> Low Availability | E26: Flags low availability or borrowing-base deficiency.

Sheet Cash Flow Stress
A1: Cash Flow Stress Test
A2: Tests whether cash flow and collateral availability support debt service under weakening cases.
A4: Metric | B4: Base | C4: Downside | D4: Stress | E4: Interpretation
A5: Revenue | B5: ='Historical Financials'!F5*(1+'ABL Assumptions'!B5) -> 24786.144 | C5: ='Historical Financials'!F5*(1+'ABL Assumptions'!C5) -> 22356.13 | D5: ='Historical Financials'!F5*(1+'ABL Assumptions'!D5) -> 19926.116 | E5: 2025 revenue adjusted by scenario shock.
A6: EBITDA margin | B6: =MAX(0,'Historical Financials'!F11+'ABL Assumptions'!B6) -> 0.032161336 | C6: =MAX(0,'Historical Financials'!F11+'ABL Assumptions'!C6) -> 0.017161336 | D6: =MAX(0,'Historical Financials'!F11+'ABL Assumptions'!D6) -> 0.002161336 | E6: 2025 EBITDA proxy margin plus scenario margin change.
A7: EBITDA proxy | B7: =B5*B6 -> 797.1555 | C7: =C5*C6 -> 383.66105 | D7: =D5*D6 -> 43.067031 | E7: Revenue x EBITDA margin.
A8: Interest cash cost | B8: ='Historical Financials'!F8+'Borrowing Base'!B22*'ABL Assumptions'!B17 -> 191.334 | C8: ='Historical Financials'!F8+'Borrowing Base'!C22*'ABL Assumptions'!C17 -> 209.37761 | D8: ='Historical Financials'!F8+'Borrowing Base'!D22*'ABL Assumptions'!D17 -> 240.54384 | E8: 2025 interest paid plus rate uplift on ABL loan balance.
A9: EBITDA / interest | B9: =B7/B8 -> 4.1663034 | C9: =C7/C8 -> 1.8323882 | D9: =D7/D8 -> 0.17904026 | E9: Primary cash-flow coverage indicator.
A10: Total debt | B10: ='Historical Financials'!F25+('Borrowing Base'!B22-'Borrowing Base'!B22) -> 5138.751 | C10: ='Historical Financials'!F25+('Borrowing Base'!C22-'Borrowing Base'!B22) -> 5302.7838 | D10: ='Historical Financials'!F25+('Borrowing Base'!D22-'Borrowing Base'!B22) -> 5466.8166 | E10: 2025 total debt plus incremental scenario draw.
A11: Debt / EBITDA | B11: =B10/B7 -> 6.4463596 | C11: =C10/C7 -> 13.821533 | D11: =D10/D7 -> 126.93739 | E11: Leverage pressure indicator.
A12: Operating cash flow proxy | B12: =B7*'ABL Assumptions'!B18 -> 558.00885 | C12: =C7*'ABL Assumptions'!C18 -> 211.01358 | D12: =D7*'ABL Assumptions'!D18 -> 15.073461 | E12: EBITDA x CFO conversion assumption.
A13: Capex | B13: =B5*'ABL Assumptions'!B19 -> 495.72288 | C13: =C5*'ABL Assumptions'!C19 -> 491.83485 | D13: =D5*'ABL Assumptions'!D19 -> 498.15289 | E13: Revenue x capex % assumption.
A14: Free cash flow | B14: =B12-B13 -> 62.285974 | C14: =C12-C13 -> -280.82127 | D14: =D12-D13 -> -483.07943 | E14: Operating cash flow proxy less capex.
A15: Excess availability | B15: ='Borrowing Base'!B23 -> 2238.7237 | C15: ='Borrowing Base'!C23 -> 1137.6027 | D15: ='Borrowing Base'!D23 -> 27.598004 | E15: Linked to borrowing-base schedule.
A16: Minimum liquidity | B16: ='Borrowing Base'!B25 -> 2715.9027 | C16: ='Borrowing Base'!C25 -> 1614.7817 | D16: ='Borrowing Base'!D25 -> 504.777 | E16: Cash + excess availability.
A17: Scenario risk rating | B17: =IF(OR(B15<0,B16<0,B9<1,B11>8),"High Risk",IF(OR(B15<500,B9<2,B11>5),"Watch","Pass")) -> Watch | C17: =IF(OR(C15<0,C16<0,C9<1,C11>8),"High Risk",IF(OR(C15<500,C9<2,C11>5),"Watch","Pass")) -> High Risk | D17: =IF(OR(D15<0,D16<0,D9<1,D11>8),"High Risk",IF(OR(D15<500,D9<2,D11>5),"Watch","Pass")) -> High Risk | E17: Pass / Watch / High Risk based on liquidity, coverage, and leverage.

Sheet Dashboard
B2: ABL Credit Dashboard: Genuine Parts Company
B3: Borrowing base, liquidity, cash-flow coverage, and downside protection summary.
B5: Base borrowing base | D5: Base excess availability | F5: Base utilization | H5: Stress excess availability | J5: Stress EBITDA / interest | L5: Stress risk rating
B6: ='Borrowing Base'!B21 -> 3879.0517 | D6: ='Borrowing Base'!B23 -> 2238.7237 | F6: ='Borrowing Base'!B24 -> 0.4228683 | H6: ='Borrowing Base'!D23 -> 27.598004 | J6: ='Cash Flow Stress'!D9 -> 0.17904026 | L6: ='Cash Flow Stress'!D17 -> High Risk
B9: Risk Alerts
B10: Alert | C10: Status | D10: Comment
B11: Low excess availability | C11: Watch | D11: Stress excess availability below $500mm threshold.
B12: High past-due AR | C12: Watch | D12: Illustrative AR aging has 90+ day and disputed ineligibles; monitor through BBC reporting.
B13: Inventory ineligibility | C13: Watch | D13: Downside/stress eligibility falls materially as slow-moving/obsolete risk rises.
B14: Customer concentration | C14: Watch | D14: Top two illustrative customers exceed 10% threshold.
B15: Borrowing base deficiency | C15: OK | D15: Stress case tests deficiency trigger.
B16: Cash-flow coverage pressure | C16: Watch | D16: Stress EBITDA / interest below 2.0x watch threshold.

Sheet Checks
A1: Model Checks
A4: Check | B4: Actual | C4: Expected / Tolerance | D4: Status | E4: Notes
A5: AR aging percentages sum to 100% | B5: ='AR Aging'!B14 -> 1 | C5: 1 | D5: =IF(ABS(B5-C5)<0.0001,"OK","Review") -> OK | E5: Illustrative aging schedule tie-out.
A6: Inventory percentages sum to 100% | B6: ='Inventory Eligibility'!B15 -> 1 | C6: 1 | D6: =IF(ABS(B6-C6)<0.0001,"OK","Review") -> OK | E6: Illustrative inventory schedule tie-out.
A7: Customer concentration sums to 100% | B7: ='Customer Concentration'!B18 -> 1 | C7: 1 | D7: =IF(ABS(B7-C7)<0.0001,"OK","Review") -> OK | E7: Illustrative concentration schedule tie-out.
A8: Base excess availability positive | B8: ='Borrowing Base'!B23 -> 2238.7237 | C8: 0 | D8: =IF(B8>C8,"OK","Review") -> OK | E8: Collateral support covers modeled ABL balance.
A9: Stress case risk rating produced | B9: ='Cash Flow Stress'!D17 -> High Risk | C9: High Risk | D9: =IF(B9<>"","OK","Review") -> OK | E9: Scenario rating formula is active.
A10: Interest fallback documented | B10: ='Historical Financials'!F8 -> 191.334 | C10: 0 | D10: =IF(B10>C10,"OK","Review") -> OK | E10: 2024-2025 use InterestPaidNet where InterestExpense is unavailable in companyfacts.
A13: Overall model status | B13: =IF(COUNTIF(D5:D10,"Review")=0,"OK","Review") -> OK
